<mujoco model="ability_hand">
  <compiler angle="radian"/>

  <asset>
    <mesh name="palm_hull" file="palm_hull.STL"/>
    <mesh name="idx-F1-hull" file="idx-F1-hull.STL"/>
    <mesh name="idx-F2-hull" file="idx-F2-hull.STL"/>
    <mesh name="thumb-F1-hull" file="thumb-F1-hull.STL"/>
    <mesh name="thumb-F2-hull" file="thumb-F2-hull.STL"/>
  </asset>

  <worldbody>
    <geom name="palm_mesh_coll" pos="0.0240477 0.00378125 0.0323296" quat="0.0442297 0.00061027 0.999021 2.70192e-05" type="mesh" mesh="palm_hull"/>
    <body name="index_L1" pos="0.028 -0.009 0.096" quat="0.71444 0.12971 -0.685961 -0.04699">
      <inertial pos="0.017755 -0.000213868 -2.02851e-05" quat="0.00502232 0.707999 -0.00737691 0.706157" mass="0.00636" diaginertia="1.05412e-06 9.77895e-07 2.84951e-07"/>
      <joint name="index_q1" pos="0 0 0" axis="0 0 1" range="0 2.0944" actuatorfrcrange="-6 6" damping="0.001" frictionloss="0.001"/>
      <geom name="index_mesh_coll_1" pos="0.0384727 0.0032577 0" quat="0.999108 0 0 0.0422244" type="mesh" mesh="idx-F1-hull"/>
      <body name="index_L2" pos="0.0384727 0.0032577 0" quat="0.999108 0 0 0.0422244">
        <inertial pos="0.0152723 -0.0100039 -3.11064e-05" quat="0.0227755 0.629561 -0.320213 0.707529" mass="0.006" diaginertia="1.13389e-06 1.13353e-06 1.86483e-07"/>
        <joint name="index_q2" pos="0 0 0" axis="0 0 1" range="0 2.6586" actuatorfrcrange="-6 6" damping="0.001" frictionloss="0.001"/>
        <geom name="index_mesh_coll_2" pos="0.0091241 0 0" quat="1 0 0 0" type="mesh" mesh="idx-F2-hull"/>
      </body>
    </body>
    <body name="middle_L1" pos="0.008 -0.012 0.099" quat="0.698369 0.103818 -0.704545 -0.0715454">
      <inertial pos="0.017755 -0.000213868 -2.02851e-05" quat="0.00502232 0.707999 -0.00737691 0.706157" mass="0.00636" diaginertia="1.05412e-06 9.77895e-07 2.84951e-07"/>
      <joint name="middle_q1" pos="0 0 0" axis="0 0 1" range="0 2.0944" actuatorfrcrange="-6 6" damping="0.001" frictionloss="0.001"/>
      <geom name="middle_mesh_coll_1" pos="0.0384727 0.0032577 0" quat="0.999108 0 0 0.0422244" type="mesh" mesh="idx-F1-hull"/>
      <body name="middle_L2" pos="0.0384727 0.0032577 0" quat="0.999108 0 0 0.0422244">
        <inertial pos="0.0152723 -0.0100039 -3.11064e-05" quat="0.0227755 0.629561 -0.320213 0.707529" mass="0.006" diaginertia="1.13389e-06 1.13353e-06 1.86483e-07"/>
        <joint name="middle_q2" pos="0 0 0" axis="0 0 1" range="0 2.6586" actuatorfrcrange="-6 6" damping="0.001" frictionloss="0.001"/>
        <geom name="middle_mesh_coll_2" pos="0.0091241 0 0" quat="1 0 0 0" type="mesh" mesh="idx-F2-hull"/>
      </body>
    </body>
    <body name="ring_L1" pos="-0.012 -0.01 0.097" quat="0.681151 0.0770537 -0.721343 -0.0987941">
      <inertial pos="0.017755 -0.000213868 -2.02851e-05" quat="0.00502232 0.707999 -0.00737691 0.706157" mass="0.00636" diaginertia="1.05412e-06 9.77895e-07 2.84951e-07"/>
      <joint name="ring_q1" pos="0 0 0" axis="0 0 1" range="0 2.0944" actuatorfrcrange="-6 6" damping="0.001" frictionloss="0.001"/>
      <geom name="ring_mesh_coll_1" pos="0.0384727 0.0032577 0" quat="0.999108 0 0 0.0422244" type="mesh" mesh="idx-F1-hull"/>
      <body name="ring_L2" pos="0.0384727 0.0032577 0" quat="0.999108 0 0 0.0422244">
        <inertial pos="0.0152723 -0.0100039 -3.11064e-05" quat="0.0227755 0.629561 -0.320213 0.707529" mass="0.006" diaginertia="1.13389e-06 1.13353e-06 1.86483e-07"/>
        <joint name="ring_q2" pos="0 0 0" axis="0 0 1" range="0 2.6586" actuatorfrcrange="-6 6" damping="0.001" frictionloss="0.001"/>
        <geom name="ring_mesh_coll_2" pos="0.0091241 0 0" quat="1 0 0 0" type="mesh" mesh="idx-F2-hull"/>
      </body>
    </body>
    <body name="pinky_L1" pos="-0.031 -0.007 0.091" quat="0.68182 0.0542329 -0.719193 -0.122235">
      <inertial pos="0.017755 -0.000213868 -2.02851e-05" quat="0.00502232 0.707999 -0.00737691 0.706157" mass="0.00636" diaginertia="1.05412e-06 9.77895e-07 2.84951e-07"/>
      <joint name="pinky_q1" pos="0 0 0" axis="0 0 1" range="0 2.0944" actuatorfrcrange="-6 6" damping="0.001" frictionloss="0.001"/>
      <geom name="pinky_mesh_coll_1" pos="0.0384727 0.0032577 0" quat="0.999108 0 0 0.0422244" type="mesh" mesh="idx-F1-hull"/>
      <body name="pinky_L2" pos="0.0384727 0.0032577 0" quat="0.999108 0 0 0.0422244">
        <inertial pos="0.0133249 -0.00815895 -4.0769e-05" quat="0.155164 0.68605 -0.165287 0.691332" mass="0.006" diaginertia="8.93744e-07 8.78977e-07 1.69753e-07"/>
        <joint name="pinky_q2" pos="0 0 0" axis="0 0 1" range="0 2.6586" actuatorfrcrange="-6 6" damping="0.001" frictionloss="0.001"/>
        <geom name="pinky_mesh_coll_2" pos="0.0091241 0 0" quat="1 0 0 0" type="mesh" mesh="idx-F2-hull"/>
      </body>
    </body>
    <body name="thumb_L1" pos="0.0240477 0.00378125 0.0323296" quat="0.00414316 -0.994629 0.0935821 -0.0440352">
      <inertial pos="0.014335 -0.00188501 -0.00504062" quat="0.364302 0.683087 0.523596 0.355703" mass="0.002" diaginertia="2.52818e-07 2.40092e-07 7.7407e-08"/>
      <joint name="thumb_q1" pos="0 0 0" axis="0 0 1" range="-2.0944 0" actuatorfrcrange="-1.2 1.2" damping="0.001" frictionloss="0.001"/>
      <geom name="thumb_coll_mesh_1" pos="0.02783 0 -0.01475" quat="0.60876 -0.793355 0 0" type="mesh" mesh="thumb-F1-hull"/>
      <body name="thumb_L2" pos="0.0278284 0 -0.0147507" quat="-0.608761 0.793353 0 0">
        <inertial pos="0.0277625 0.00562171 -0.00410855" quat="-0.172587 0.694893 0.121684 0.687408" mass="0.06" diaginertia="2.58599e-05 2.49484e-05 4.76107e-06"/>
        <joint name="thumb_q2" pos="0 0 0" axis="0 0 1" range="0 2.0944" actuatorfrcrange="-6 6" damping="0.001" frictionloss="0.001"/>
        <geom name="thumb_hull_mesh_2" pos="0.06519 0.02334 -0.00393" quat="1.30724e-06 0.985259 0.171069 2.26974e-07" type="mesh" mesh="thumb-F2-hull"/>
      </body>
    </body>
  </worldbody>
</mujoco>
