<mujoco model="right_ability_hand">
  <compiler angle="radian"/>

  <asset>
    <mesh name="wristmesh" file="wristmesh.STL"/>
    <mesh name="FB_palm_ref_MIR" file="FB_palm_ref_MIR.STL"/>
    <mesh name="idx-F1" file="idx-F1.STL"/>
    <mesh name="idx-F2" file="idx-F2.STL"/>
    <mesh name="thumb-F1-MIR" file="thumb-F1-MIR.STL"/>
    <mesh name="thumb-F2" file="thumb-F2.STL"/>
  </asset>

  <worldbody>
    <geom name="world" type="mesh" mesh="wristmesh"/>
    <geom name="right_hand_wrist_mesh" pos="0.042 0 0" quat="0.707388 0 0.706825 0" type="mesh" mesh="wristmesh"/>
    <geom name="right_hand_palm_mesh" pos="0.0743105 0.00378125 0.0240734" quat="0.737421 0.0004126 -0.675433 -0.000450467" type="mesh" mesh="FB_palm_ref_MIR"/>
    <body name="right_hand_index_L1" pos="0.137848 -0.00927034 0.0279979" quat="0.990199 -0.0586241 -0.0205843 -0.12508">
      <inertial pos="0.0224191 -0.000157982 -1.31987e-05" quat="-0.00406251 0.706621 0.00934715 0.707518" mass="0.00635888" diaginertia="3.81765e-06 3.69601e-06 2.96432e-07"/>
      <joint name="right_hand_index_q1" pos="0 0 0" axis="0 0 1" range="0 2.0944" actuatorfrcrange="-0.2 0.2" damping="0.001" frictionloss="0.001"/>
      <geom name="right_hand_index_mesh_1" pos="0.0384727 0.0032577 0" quat="0.999108 0 0 0.0422244" type="mesh" mesh="idx-F1"/>
      <body name="right_hand_index_L2" pos="0.0384727 0.0032577 0" quat="0.999108 0 0 0.0422244">
        <inertial pos="0.0133682 -0.00875392 -2.886e-05" quat="-0.161363 0.673074 0.216775 0.688434" mass="0.00645" diaginertia="2.64645e-06 2.63553e-06 1.71391e-07"/>
        <joint name="right_hand_index_q2" pos="0 0 0" axis="0 0 1" range="0 2.6586" actuatorfrcrange="-0.2 0.2" damping="0.001" frictionloss="0.001"/>
        <geom name="right_hand_index_mesh_2" pos="0.0091241 0 0" quat="1 0 0 0" type="mesh" mesh="idx-F2"/>
      </body>
    </body>
    <body name="right_hand_middle_L1" pos="0.141057 -0.0115172 0.00849606" quat="0.992042 -0.0225318 0.00396524 -0.123811">
      <inertial pos="0.0224191 -0.000157982 -1.31987e-05" quat="-0.00406251 0.706621 0.00934715 0.707518" mass="0.00635888" diaginertia="3.81765e-06 3.69601e-06 2.96432e-07"/>
      <joint name="right_hand_middle_q1" pos="0 0 0" axis="0 0 1" range="0 2.0944" actuatorfrcrange="-0.2 0.2" damping="0.001" frictionloss="0.001"/>
      <geom name="right_hand_middle_mesh_1" pos="0.0384727 0.0032577 0" quat="0.999108 0 0 0.0422244" type="mesh" mesh="idx-F1"/>
      <body name="right_hand_middle_L2" pos="0.0384727 0.0032577 0" quat="0.999108 0 0 0.0422244">
        <inertial pos="0.0133682 -0.00875392 -2.886e-05" quat="-0.161363 0.673074 0.216775 0.688434" mass="0.00645" diaginertia="2.64645e-06 2.63553e-06 1.71391e-07"/>
        <joint name="right_hand_middle_q2" pos="0 0 0" axis="0 0 1" range="0 2.6586" actuatorfrcrange="-0.2 0.2" damping="0.001" frictionloss="0.001"/>
        <geom name="right_hand_middle_mesh_2" pos="0.0091241 0 0" quat="1 0 0 0" type="mesh" mesh="idx-F2"/>
      </body>
    </body>
    <body name="right_hand_ring_L1" pos="0.138713 -0.0103946 -0.0116759" quat="0.991745 0.0153864 0.0280156 -0.124176">
      <inertial pos="0.0224191 -0.000157982 -1.31987e-05" quat="-0.00406251 0.706621 0.00934715 0.707518" mass="0.00635888" diaginertia="3.81765e-06 3.69601e-06 2.96432e-07"/>
      <joint name="right_hand_ring_q1" pos="0 0 0" axis="0 0 1" range="0 2.0944" actuatorfrcrange="-0.2 0.2" damping="0.001" frictionloss="0.001"/>
      <geom name="right_hand_ring_mesh_1" pos="0.0384727 0.0032577 0" quat="0.999108 0 0 0.0422244" type="mesh" mesh="idx-F1"/>
      <body name="right_hand_ring_L2" pos="0.0384727 0.0032577 0" quat="0.999108 0 0 0.0422244">
        <inertial pos="0.0133682 -0.00875392 -2.886e-05" quat="-0.161363 0.673074 0.216775 0.688434" mass="0.00645" diaginertia="2.64645e-06 2.63553e-06 1.71391e-07"/>
        <joint name="right_hand_ring_q2" pos="0 0 0" axis="0 0 1" range="0 2.6586" actuatorfrcrange="-0.2 0.2" damping="0.001" frictionloss="0.001"/>
        <geom name="right_hand_ring_mesh_2" pos="0.0091241 0 0" quat="1 0 0 0" type="mesh" mesh="idx-F2"/>
      </body>
    </body>
    <body name="right_hand_pinky_L1" pos="0.132759 -0.00716283 -0.030791" quat="0.990649 0.0481002 0.0261065 -0.124978">
      <inertial pos="0.0224191 -0.000157982 -1.31987e-05" quat="-0.00406251 0.706621 0.00934715 0.707518" mass="0.00635888" diaginertia="3.81765e-06 3.69601e-06 2.96432e-07"/>
      <joint name="right_hand_pinky_q1" pos="0 0 0" axis="0 0 1" range="0 2.0944" actuatorfrcrange="-0.2 0.2" damping="0.001" frictionloss="0.001"/>
      <geom name="right_hand_pinky_mesh_1" pos="0.0384727 0.0032577 0" quat="0.999108 0 0 0.0422244" type="mesh" mesh="idx-F1"/>
      <body name="right_hand_pinky_L2" pos="0.0384727 0.0032577 0" quat="0.999108 0 0 0.0422244">
        <inertial pos="0.0133682 -0.00875392 -2.886e-05" quat="-0.161363 0.673074 0.216775 0.688434" mass="0.00645" diaginertia="2.64645e-06 2.63553e-06 1.71391e-07"/>
        <joint name="right_hand_pinky_q2" pos="0 0 0" axis="0 0 1" range="0 2.6586" actuatorfrcrange="-0.2 0.2" damping="0.001" frictionloss="0.001"/>
        <geom name="right_hand_pinky_mesh_2" pos="0.0091241 0 0" quat="1 0 0 0" type="mesh" mesh="idx-F2"/>
      </body>
    </body>
    <body name="right_hand_thumb_L1" pos="0.0743105 0.00378125 0.0240734" quat="-0.0640919 0.734094 -0.0699739 0.672386">
      <inertial pos="0.014606 -0.00189085 -0.00311554" quat="0.306728 0.531258 0.293089 0.733336" mass="0.00268342" diaginertia="8.14795e-07 7.42718e-07 1.14409e-07"/>
      <joint name="right_hand_thumb_q1" pos="0 0 0" axis="0 0 1" range="-2.0944 0" actuatorfrcrange="-0.2 0.2" damping="0.001" frictionloss="0.001"/>
      <geom name="right_hand_thumb_mesh_1" pos="0.0278284 0 0.0147507" quat="0.608761 0.793353 0 0" type="mesh" mesh="thumb-F1-MIR"/>
      <body name="right_hand_thumb_L2" pos="0.0278284 0 0.0147507" quat="0.608761 0.793353 0 0">
        <inertial pos="0.0300205 0.00559476 -0.00415044" quat="0.00721249 0.656735 -0.223684 0.720148" mass="0.0055" diaginertia="1.80207e-05 1.70892e-05 2.87855e-06"/>
        <joint name="right_hand_thumb_q2" pos="0 0 0" axis="0 0 1" range="0 2.0944" actuatorfrcrange="-0.2 0.2" damping="0.001" frictionloss="0.001"/>
        <geom name="right_hand_thumb_mesh_2" pos="0.0651867 0.0233402 0.00393483" quat="3.21978e-07 -0.985259 -0.171069 5.59046e-08" type="mesh" mesh="thumb-F2"/>
      </body>
    </body>
  </worldbody>
</mujoco>
