<mujoco model="right_ability_hand">
  <compiler angle="radian"/>

  <asset>
    <mesh name="wristmesh" file="wristmesh.STL"/>
    <mesh name="FB_palm_ref" file="FB_palm_ref.STL"/>
    <mesh name="idx-F1" file="idx-F1.STL"/>
    <mesh name="idx-F2" file="idx-F2.STL"/>
    <mesh name="thumb-F1" file="thumb-F1.STL"/>
    <mesh name="thumb-F2" file="thumb-F2.STL"/>
  </asset>

  <worldbody>
    <geom name="world" type="mesh" mesh="wristmesh"/>
    <geom name="right_hand_wrist_mesh" pos="0.042 0 0" quat="0.000844632 -0.707107 -0.000281544 -0.707107" type="mesh" mesh="wristmesh"/>
    <geom name="right_hand_palm_mesh" pos="0.0743356 -0.0037489 0.0240447" quat="0.000769257 0.67514 0.000418933 -0.737689" type="mesh" mesh="FB_palm_ref"/>
    <body name="right_hand_index_L1" pos="0.137856 0.00940078 0.027929" quat="-0.0590842 0.990084 0.125838 0.0201931">
      <inertial pos="0.0224191 -0.000157982 -1.31987e-05" quat="-0.00406251 0.706621 0.00934715 0.707518" mass="0.00635888" diaginertia="3.81765e-06 3.69601e-06 2.96432e-07"/>
      <joint name="right_hand_index_q1" pos="0 0 0" axis="0 0 1" range="0 2.0944" actuatorfrcrange="-0.2 0.2" damping="0.001" frictionloss="0.001"/>
      <geom name="right_hand_index_mesh_1" pos="0.0384727 0.0032577 0" quat="0.999108 0 0 0.0422244" type="mesh" mesh="idx-F1"/>
      <body name="right_hand_index_L2" pos="0.0384727 0.0032577 0" quat="0.999108 0 0 0.0422244">
        <inertial pos="0.0133682 -0.00875392 -2.886e-05" quat="-0.161363 0.673074 0.216775 0.688434" mass="0.00645" diaginertia="2.64645e-06 2.63553e-06 1.71391e-07"/>
        <joint name="right_hand_index_q2" pos="0 0 0" axis="0 0 1" range="0 2.6586" actuatorfrcrange="-0.2 0.2" damping="0.001" frictionloss="0.001"/>
        <geom name="right_hand_index_mesh_2" pos="0.0091241 0 0" quat="1 0 0 0" type="mesh" mesh="idx-F2"/>
      </body>
    </body>
    <body name="right_hand_middle_L1" pos="0.141045 0.0116683 0.00842641" quat="-0.0229726 0.991932 0.124593 -0.00432892">
      <inertial pos="0.0224191 -0.000157982 -1.31987e-05" quat="-0.00406251 0.706621 0.00934715 0.707518" mass="0.00635888" diaginertia="3.81765e-06 3.69601e-06 2.96432e-07"/>
      <joint name="right_hand_middle_q1" pos="0 0 0" axis="0 0 1" range="0 2.0944" actuatorfrcrange="-0.2 0.2" damping="0.001" frictionloss="0.001"/>
      <geom name="right_hand_middle_mesh_1" pos="0.0384727 0.0032577 0" quat="0.999108 0 0 0.0422244" type="mesh" mesh="idx-F1"/>
      <body name="right_hand_middle_L2" pos="0.0384727 0.0032577 0" quat="0.999108 0 0 0.0422244">
        <inertial pos="0.0133682 -0.00875392 -2.886e-05" quat="-0.161363 0.673074 0.216775 0.688434" mass="0.00645" diaginertia="2.64645e-06 2.63553e-06 1.71391e-07"/>
        <joint name="right_hand_middle_q2" pos="0 0 0" axis="0 0 1" range="0 2.6586" actuatorfrcrange="-0.2 0.2" damping="0.001" frictionloss="0.001"/>
        <geom name="right_hand_middle_mesh_2" pos="0.0091241 0 0" quat="1 0 0 0" type="mesh" mesh="idx-F2"/>
      </body>
    </body>
    <body name="right_hand_ring_L1" pos="0.138687 0.010558 -0.0117446" quat="0.0149647 0.991641 0.124983 -0.0283488">
      <inertial pos="0.0224191 -0.000157982 -1.31987e-05" quat="-0.00406251 0.706621 0.00934715 0.707518" mass="0.00635888" diaginertia="3.81765e-06 3.69601e-06 2.96432e-07"/>
      <joint name="right_hand_ring_q1" pos="0 0 0" axis="0 0 1" range="0 2.0944" actuatorfrcrange="-0.2 0.2" damping="0.001" frictionloss="0.001"/>
      <geom name="right_hand_ring_mesh_1" pos="0.0384727 0.0032577 0" quat="0.999108 0 0 0.0422244" type="mesh" mesh="idx-F1"/>
      <body name="right_hand_ring_L2" pos="0.0384727 0.0032577 0" quat="0.999108 0 0 0.0422244">
        <inertial pos="0.0133682 -0.00875392 -2.886e-05" quat="-0.161363 0.673074 0.216775 0.688434" mass="0.00645" diaginertia="2.64645e-06 2.63553e-06 1.71391e-07"/>
        <joint name="right_hand_ring_q2" pos="0 0 0" axis="0 0 1" range="0 2.6586" actuatorfrcrange="-0.2 0.2" damping="0.001" frictionloss="0.001"/>
        <geom name="right_hand_ring_mesh_2" pos="0.0091241 0 0" quat="1 0 0 0" type="mesh" mesh="idx-F2"/>
      </body>
    </body>
    <body name="right_hand_pinky_L1" pos="0.132723 0.0073319 -0.0308575" quat="0.0476771 0.990558 0.125797 -0.0264129">
      <inertial pos="0.0224191 -0.000157982 -1.31987e-05" quat="-0.00406251 0.706621 0.00934715 0.707518" mass="0.00635888" diaginertia="3.81765e-06 3.69601e-06 2.96432e-07"/>
      <joint name="right_hand_pinky_q1" pos="0 0 0" axis="0 0 1" range="0 2.0944" actuatorfrcrange="-0.2 0.2" damping="0.001" frictionloss="0.001"/>
      <geom name="right_hand_pinky_mesh_1" pos="0.0384727 0.0032577 0" quat="0.999108 0 0 0.0422244" type="mesh" mesh="idx-F1"/>
      <body name="right_hand_pinky_L2" pos="0.0384727 0.0032577 0" quat="0.999108 0 0 0.0422244">
        <inertial pos="0.0133682 -0.00875392 -2.886e-05" quat="-0.161363 0.673074 0.216775 0.688434" mass="0.00645" diaginertia="2.64645e-06 2.63553e-06 1.71391e-07"/>
        <joint name="right_hand_pinky_q2" pos="0 0 0" axis="0 0 1" range="0 2.6586" actuatorfrcrange="-0.2 0.2" damping="0.001" frictionloss="0.001"/>
        <geom name="right_hand_pinky_mesh_2" pos="0.0091241 0 0" quat="1 0 0 0" type="mesh" mesh="idx-F2"/>
      </body>
    </body>
    <body name="right_hand_thumb_L1" pos="0.0743356 -0.0037489 0.0240447" quat="0.734331 -0.0632364 -0.672172 0.0703166">
      <inertial pos="0.014606 -0.00189085 -0.00311554" quat="0.306728 0.531258 0.293089 0.733336" mass="0.00268342" diaginertia="8.14795e-07 7.42718e-07 1.14409e-07"/>
      <joint name="right_hand_thumb_q1" pos="0 0 0" axis="0 0 1" range="-2.0944 0" actuatorfrcrange="-0.2 0.2" damping="0.001" frictionloss="0.001"/>
      <geom name="right_hand_thumb_mesh_1" pos="0.0278284 0 -0.0147507" quat="-0.608761 0.793353 0 0" type="mesh" mesh="thumb-F1"/>
      <body name="right_hand_thumb_L2" pos="0.0278284 0 -0.0147507" quat="-0.608761 0.793353 0 0">
        <inertial pos="0.0300205 0.00559476 -0.00415044" quat="0.00721249 0.656735 -0.223684 0.720148" mass="0.0055" diaginertia="1.80207e-05 1.70892e-05 2.87855e-06"/>
        <joint name="right_hand_thumb_q2" pos="0 0 0" axis="0 0 1" range="0 2.0944" actuatorfrcrange="-0.2 0.2" damping="0.001" frictionloss="0.001"/>
        <geom name="right_hand_thumb_mesh_2" pos="0.0651867 0.0233402 -0.00393483" quat="3.21978e-07 0.985259 0.171069 5.59046e-08" type="mesh" mesh="thumb-F2"/>
      </body>
    </body>
  </worldbody>
</mujoco>
